<?xml version='1.0'?>

<robot name="my_robot" xmlns:xacro="http://www.ros.org/wiki/xacro">

  <!-- <xacro:arg name="robot_namespace" default=""/> -->

  <!-- <xacro:property name="namespace" value="$(arg robot_namespace)" /> -->

  <xacro:include filename="$(find whereAmI)/urdf/my_robot.gazebo" />

  <link name="robot_footprint"></link>

  <joint name="robot_footprint_joint" type="fixed">
    <origin xyz="0 0 0" rpy="0 0 0"/>
    <parent link="robot_footprint"/>
    <child link="chassis"/>
  </joint>  

  <link name="chassis">

    <pose>0 0 0 0 0 0</pose>

    <inertial>
      <mass value="15.0"/>
      <origin xyz="0.0 0 0" rpy="0 0 0"/>
      <inertia
        ixx="0.1" ixy="0" ixz="0"
        iyy="0.1" iyz="0"
        izz="0.1"
      />
    </inertial>
    
    <collision name='collision'>
      <origin xyz="0 0 -0.05" rpy="0 0 0"/>
      <geometry>
        <mesh scale="0.5 0.5 0.5" filename="package://whereAmI/meshes/base_chassis.dae"/>    
      </geometry>
    </collision>
    
    <visual name="chassis_visual">
      <origin xyz="0 0 -0.05" rpy="0 0 0"/>
      <geometry>
        <mesh scale="0.5 0.5 0.5" filename="package://whereAmI/meshes/base_chassis.dae"/> 
      </geometry>
    </visual>
  </link>

  <link name="front_left_wheel">

    <inertial>
      <mass value="5.0"/>
      <origin xyz="0.0 0 0" rpy="0 1.5707 1.5707"/>
      <inertia
        ixx="0.1" ixy="0" ixz="0"
        iyy="0.1" iyz="0"
        izz="0.1"
      />
    </inertial>    

    <collision name='collision'>
      <origin xyz="0 0 0" rpy="0 1.5707 1.5707"/>
      <geometry>
        <cylinder radius="0.075" length="0.05"/>   
      </geometry>
    </collision>
    
    <visual name="front_left_wheel_visual">
      <origin xyz="0 0 0" rpy="0 1.5707 1.5707"/>
      <geometry>
        <cylinder radius="0.075" length="0.05"/> 
      </geometry>
    </visual>

  </link>

  <link name="front_right_wheel">

    <inertial>
      <mass value="5.0"/>
      <origin xyz="0.0 0 0" rpy="0 1.5707 1.5707"/>
      <inertia
        ixx="0.1" ixy="0" ixz="0"
        iyy="0.1" iyz="0"
        izz="0.1"
      />
    </inertial>    

    <collision name='collision'>
      <origin xyz="0 0 0" rpy="0 1.5707 1.5707"/>
      <geometry>
        <cylinder radius="0.075" length="0.05"/>   
      </geometry>
    </collision>
    
    <visual name="front_right_wheel_visual">
      <origin xyz="0 0 0" rpy="0 1.5707 1.5707"/>
      <geometry>
        <cylinder radius="0.075" length="0.05"/> 
      </geometry>
    </visual>

  </link>

  <link name="rear_left_wheel">

    <inertial>
      <mass value="5.0"/>
      <origin xyz="0.0 0 0" rpy="0 1.5707 1.5707"/>
      <inertia
        ixx="0.1" ixy="0" ixz="0"
        iyy="0.1" iyz="0"
        izz="0.1"
      />
    </inertial>    

    <collision name='collision'>
      <origin xyz="0 0 0" rpy="0 1.5707 1.5707"/>
      <geometry>
        <cylinder radius="0.075" length="0.05"/>   
      </geometry>
    </collision>
    
    <visual name="rear_left_wheel_visual">
      <origin xyz="0 0 0" rpy="0 1.5707 1.5707"/>
      <geometry>
        <cylinder radius="0.075" length="0.05"/> 
      </geometry>
    </visual>

  </link>

  <link name="rear_right_wheel">

    <inertial>
      <mass value="5.0"/>
      <origin xyz="0.0 0 0" rpy="0 1.5707 1.5707"/>
      <inertia
        ixx="0.1" ixy="0" ixz="0"
        iyy="0.1" iyz="0"
        izz="0.1"
      />
    </inertial>    

    <collision name='collision'>
      <origin xyz="0 0 0" rpy="0 1.5707 1.5707"/>
      <geometry>
        <cylinder radius="0.075" length="0.05"/>   
      </geometry>
    </collision>
    
    <visual name="rear_right_wheel_visual">
      <origin xyz="0 0 0" rpy="0 1.5707 1.5707"/>
      <geometry>
        <cylinder radius="0.075" length="0.05"/> 
      </geometry>
    </visual>

  </link>

  <joint name="front_left_wheel_hinge" type="continuous">
    <origin xyz="0.125 0.15 -0.0225" rpy="0 0 0"/>
    <axis xyz="0 1 0" rpy="0 0 0"/>
    <limit effort="10000" velocity="1000"/>
    <dynamics damping="1.0" friction="1.0"/>
    <parent link="chassis"/>
    <child link="front_left_wheel"/>
  </joint>

  <transmission name="front_left_wheel_trans" type="SimpleTransmission">
    <type>transmission_interface/SimpleTransmission</type>
    <actuator name="front_left_wheel_motor">
      <mechanicalReduction>1</mechanicalReduction>
    </actuator>
    <joint name="front_left_wheel_hinge">
      <hardwareInterface>hardware_interface/EffortJointInterface</hardwareInterface>
    </joint>
  </transmission>

  <joint name="front_right_wheel_hinge" type="continuous">
    <origin xyz="0.125 -0.15 -0.0225" rpy="0 0 0"/>
    <axis xyz="0 1 0" rpy="0 0 0"/>
    <limit effort="10000" velocity="1000"/>
    <dynamics damping="1.0" friction="1.0"/>
    <parent link="chassis"/>
    <child link="front_right_wheel"/>
  </joint>

  <transmission name="front_right_wheel_trans" type="SimpleTransmission">
    <type>transmission_interface/SimpleTransmission</type>
    <actuator name="front_right_wheel_motor">
      <mechanicalReduction>1</mechanicalReduction>
    </actuator>
    <joint name="front_right_wheel_hinge">
      <hardwareInterface>hardware_interface/EffortJointInterface</hardwareInterface>
    </joint>
  </transmission>

  <joint name="rear_left_wheel_hinge" type="continuous">
    <origin xyz="-0.125 0.15 -0.0225" rpy="0 0 0"/>
    <axis xyz="0 1 0" rpy="0 0 0"/>
    <limit effort="10000" velocity="1000"/>
    <dynamics damping="1.0" friction="1.0"/>
    <parent link="chassis"/>
    <child link="rear_left_wheel"/>
  </joint>

  <transmission name="rear_left_wheel_trans" type="SimpleTransmission">
    <type>transmission_interface/SimpleTransmission</type>
    <actuator name="rear_left_wheel_motor">
      <mechanicalReduction>1</mechanicalReduction>
    </actuator>
    <joint name="rear_left_wheel_hinge">
      <hardwareInterface>hardware_interface/EffortJointInterface</hardwareInterface>
    </joint>
  </transmission>

  <joint name="rear_right_wheel_hinge" type="continuous">
    <origin xyz="-0.125 -0.15 -0.0225" rpy="0 0 0"/>
    <axis xyz="0 1 0" rpy="0 0 0"/>
    <limit effort="10000" velocity="1000"/>
    <dynamics damping="1.0" friction="1.0"/>
    <parent link="chassis"/>
    <child link="rear_right_wheel"/>
  </joint>

  <transmission name="rear_right_wheel_trans" type="SimpleTransmission">
    <type>transmission_interface/SimpleTransmission</type>
    <actuator name="rear_right_wheel_motor">
      <mechanicalReduction>1</mechanicalReduction>
    </actuator>
    <joint name="rear_right_wheel_hinge">
      <hardwareInterface>hardware_interface/EffortJointInterface</hardwareInterface>
    </joint>
  </transmission>

  <link name="rear_right_wheel_strut">

    <inertial>
      <mass value="5.0"/>
      <origin xyz="0.0 0 0" rpy="0 1.5707 1.5707"/>
      <inertia
        ixx="0.1" ixy="0" ixz="0"
        iyy="0.1" iyz="0"
        izz="0.1"
      />
    </inertial>    

    <collision name='collision'>
      <origin xyz="0 0 0" rpy="0 1.5707 1.5707"/>
      <geometry>
        <cylinder radius="0.025" length="0.025"/>   
      </geometry>
    </collision>
    
    <visual name="rear_right_wheel_strut_visual">
      <origin xyz="0 0 0" rpy="0 1.5707 1.5707"/>
      <geometry>
        <cylinder radius="0.025" length="0.025"/> 
      </geometry>
    </visual>

  </link>

  <joint name="rear_right_wheel_strut_joint" type="fixed">
    <origin xyz="-0.125 0.1125 -0.025" rpy="0 0 0"/>
    <axis xyz="0 1 0" rpy="0 0 0"/>
    <parent link="chassis"/>
    <child link="rear_right_wheel_strut"/>
  </joint>

  <link name="rear_left_wheel_strut">

    <inertial>
      <mass value="5.0"/>
      <origin xyz="0.0 0 0" rpy="0 1.5707 1.5707"/>
      <inertia
        ixx="0.1" ixy="0" ixz="0"
        iyy="0.1" iyz="0"
        izz="0.1"
      />
    </inertial>    

    <collision name='collision'>
      <origin xyz="0 0 0" rpy="0 1.5707 1.5707"/>
      <geometry>
        <cylinder radius="0.025" length="0.025"/>   
      </geometry>
    </collision>
    
    <visual name="rear_left_wheel_strut_visual">
      <origin xyz="0 0 0" rpy="0 1.5707 1.5707"/>
      <geometry>
        <cylinder radius="0.025" length="0.025"/> 
      </geometry>
    </visual>
  </link>

  <joint name="rear_left_wheel_strut_joint" type="fixed">
    <origin xyz="-0.125 -0.1125 -0.025" rpy="0 0 0"/>
    <axis xyz="0 1 0" rpy="0 0 0"/>
    <parent link="chassis"/>
    <child link="rear_left_wheel_strut"/>
  </joint>

  <link name="front_right_wheel_strut">

    <inertial>
      <mass value="5.0"/>
      <origin xyz="0.0 0 0" rpy="0 1.5707 1.5707"/>
      <inertia
        ixx="0.1" ixy="0" ixz="0"
        iyy="0.1" iyz="0"
        izz="0.1"
      />
    </inertial>    

    <collision name='collision'>
      <origin xyz="0 0 0" rpy="0 1.5707 1.5707"/>
      <geometry>
        <cylinder radius="0.025" length="0.025"/>   
      </geometry>
    </collision>
    
    <visual name="front_right_wheel_strut_visual">
      <origin xyz="0 0 0" rpy="0 1.5707 1.5707"/>
      <geometry>
        <cylinder radius="0.025" length="0.025"/> 
      </geometry>
    </visual>

  </link>

  <joint name="front_right_wheel_strut_joint" type="fixed">
    <origin xyz="0.125 0.1125 -0.025" rpy="0 0 0"/>
    <axis xyz="0 1 0" rpy="0 0 0"/>
    <parent link="chassis"/>
    <child link="front_right_wheel_strut"/>
  </joint>

  <link name="front_left_wheel_strut">

    <inertial>
      <mass value="5.0"/>
      <origin xyz="0.0 0 0" rpy="0 1.5707 1.5707"/>
      <inertia
        ixx="0.1" ixy="0" ixz="0"
        iyy="0.1" iyz="0"
        izz="0.1"
      />
    </inertial>    

    <collision name='collision'>
      <origin xyz="0 0 0" rpy="0 1.5707 1.5707"/>
      <geometry>
        <cylinder radius="0.025" length="0.025"/>   
      </geometry>
    </collision>
    
    <visual name="front_left_wheel_strut_visual">
      <origin xyz="0 0 0" rpy="0 1.5707 1.5707"/>
      <geometry>
        <cylinder radius="0.025" length="0.025"/> 
      </geometry>
    </visual>
  </link>

  <joint name="front_left_wheel_strut_joint" type="fixed">
    <origin xyz="0.125 -0.1125 -0.025" rpy="0 0 0"/>
    <axis xyz="0 1 0" rpy="0 0 0"/>
    <parent link="chassis"/>
    <child link="front_left_wheel_strut"/>
  </joint>

  <link name="battery_holder">

    <inertial>
      <mass value="0.00001"/>
      <origin xyz="0.0 0 0" rpy="0 0 0"/>
      <inertia
        ixx="0.000001" ixy="0" ixz="0"
        iyy="0.000001" iyz="0"
        izz="0.000001"
      />
    </inertial>    

    <collision name='collision'>
      <origin xyz="0 0 0" rpy="0 0 0"/>
      <geometry>
        <mesh scale="0.5 0.5 0.5" filename="package://whereAmI/meshes/battery_holder.dae"/>   
      </geometry>
    </collision>
    
    <visual name="battery_holder_visual">
      <origin xyz="0 0 0" rpy="0 0 0"/>
      <geometry>
        <mesh scale="0.5 0.5 0.5" filename="package://whereAmI/meshes/battery_holder.dae"/> 
      </geometry>
    </visual>

  </link>

  <link name="battery">

    <inertial>
      <mass value="0.00001"/>
      <origin xyz="0.0 0 0" rpy="0 0 0"/>
      <inertia
        ixx="0.000001" ixy="0" ixz="0"
        iyy="0.000001" iyz="0"
        izz="0.000001"
      />
    </inertial>    

    <collision name='collision'>
      <origin xyz="0 0 0" rpy="0 0 0"/>
      <geometry>
        <mesh scale="0.5 0.5 0.5" filename="package://whereAmI/meshes/battery_holder.dae"/>   
      </geometry>
    </collision>
    
    <visual name="battery_visual">
      <origin xyz="0 0 0" rpy="0 0 0"/>
      <geometry>
        <mesh scale="0.5 0.5 0.5" filename="package://whereAmI/meshes/battery.dae"/> 
      </geometry>
    </visual>

  </link>

  <link name="cpu_holder">

    <inertial>
      <mass value="0.00001"/>
      <origin xyz="0.0 0 0" rpy="0 0 0"/>
      <inertia
        ixx="0.000001" ixy="0" ixz="0"
        iyy="0.000001" iyz="0"
        izz="0.000001"
      />
    </inertial>    

    <collision name='collision'>
      <origin xyz="0 0 0" rpy="0 0 0"/>
      <geometry>
        <mesh scale="0.5 0.5 0.5" filename="package://whereAmI/meshes/cpu_holder.dae"/>   
      </geometry>
    </collision>
    
    <visual name="cpu_holder_visual">
      <origin xyz="0 0 0" rpy="0 0 0"/>
      <geometry>
        <mesh scale="0.5 0.5 0.5" filename="package://whereAmI/meshes/cpu_holder.dae"/> 
      </geometry>
    </visual>

  </link>

  <link name="camera_holder">

    <inertial>
      <mass value="0.00001"/>
      <origin xyz="0.0 0 0" rpy="0 0 0"/>
      <inertia
        ixx="0.000001" ixy="0" ixz="0"
        iyy="0.000001" iyz="0"
        izz="0.000001"
      />
    </inertial>    

    <collision name='collision'>
      <origin xyz="0 0 0" rpy="0 0 0"/>
      <geometry>
        <mesh scale="0.5 0.5 0.5" filename="package://whereAmI/meshes/camera_holder.dae"/>   
      </geometry>
    </collision>
    
    <visual name="camera_holder_visual">
      <origin xyz="0 0 0" rpy="0 0 0"/>
      <geometry>
        <mesh scale="0.5 0.5 0.5" filename="package://whereAmI/meshes/camera_holder.dae"/> 
      </geometry>
    </visual>

  </link>

  <joint name="battery_holder_joint" type="fixed">
    <origin xyz="0 0 0" rpy="0 0 0"/>
    <axis xyz="0 1 0" rpy="0 0 0"/>
    <parent link="chassis"/>
    <child link="battery_holder"/>
  </joint>

  <joint name="battery_joint" type="fixed">
    <origin xyz="0 0 0.006" rpy="0 0 0"/>
    <axis xyz="0 1 0" rpy="0 0 0"/>
    <parent link="chassis"/>
    <child link="battery"/>
  </joint>

  <joint name="cpu_holder_joint" type="fixed">
    <origin xyz="-0.125 0 0" rpy="0 0 0"/>
    <axis xyz="0 1 0" rpy="0 0 0"/>
    <parent link="chassis"/>
    <child link="cpu_holder"/>
  </joint>

  <joint name="camera_holder_joint" type="fixed">
    <origin xyz="0.160 0 0" rpy="0 0 0"/>
    <axis xyz="0 1 0" rpy="0 0 0"/>
    <parent link="chassis"/>
    <child link="camera_holder"/>
  </joint>

  <link name="hokuyo">

    <inertial>
      <mass value="0.00001"/>
      <origin xyz="0.0 0 0" rpy="0 0 0"/>
      <inertia
        ixx="0.000001" ixy="0" ixz="0"
        iyy="0.000001" iyz="0"
        izz="0.000001"
      />
    </inertial>    

    <collision name='collision'>
      <origin xyz="0 0 0" rpy="0 0 0"/>
      <geometry>
        <box size="0.1 0.1 0.1"/>   
      </geometry>
    </collision>
    
    <visual name="hokuyo_visual">
      <origin xyz="0 0 0" rpy="0 0 0"/>
      <geometry>
        <mesh scale="0.5 0.5 0.5" filename="package://whereAmI/meshes/hokuyo.dae"/> 
      </geometry>
    </visual>

  </link>

  <link name="camera">

    <inertial>
      <mass value="0.1"/>
      <origin xyz="0.0 0 0" rpy="0 0 0"/>
      <box_inertia m="0.1" x="0.05" y="0.05" z="0.05"/>
      <inertia
        ixx="0.000001" ixy="0" ixz="0"
        iyy="0.000001" iyz="0"
        izz="0.000001"
      />
    </inertial>    

    <collision name='collision'>
      <origin xyz="0 0 0" rpy="0 0 0"/>
      <geometry>
        <box size="0.003 0.015 0.015"/>   
      </geometry>
    </collision>
    
    <visual name="camera_visual">
      <origin xyz="0 0 0" rpy="0 0 0"/>
      <geometry>
        <box size="0.003 0.015 0.015"/> 
      </geometry>
    </visual>

  </link>

  <link name="ckt_board">

    <inertial>
      <mass value="0.00001"/>
      <origin xyz="0.0 0 0" rpy="0 0 0"/>
      <inertia
        ixx="0.000001" ixy="0" ixz="0"
        iyy="0.000001" iyz="0"
        izz="0.000001"
      />
    </inertial>    

    <collision name='collision'>
      <origin xyz="0 0 0" rpy="0 0 0"/>
      <geometry>
        <mesh scale="0.7 0.7 0.7" filename="package://whereAmI/meshes/ckt_board.dae"/>   
      </geometry>
    </collision>
    
    <visual name="ckt_board_visual">
      <origin xyz="0 0 0" rpy="0 0 0"/>
      <geometry>
        <mesh scale="0.7 0.7 0.7" filename="package://whereAmI/meshes/ckt_board.dae"/> 
      </geometry>
    </visual>

  </link>

  <joint name="hokuyo_joint" type="fixed">
    <origin xyz="0 0 0.115" rpy="0 0 0"/>
    <axis xyz="0 1 0" rpy="0 0 0"/>
    <parent link="battery_holder"/>
    <child link="hokuyo"/>
  </joint>

  <joint name="camera_joint" type="fixed">
    <origin xyz="0.175 0 0.04" rpy="0 0 0"/>
    <axis xyz="0 1 0" rpy="0 0 0"/>
    <parent link="chassis"/>
    <child link="camera"/>
  </joint>

  <joint name="ckt_board_joint" type="fixed">
    <origin xyz="0 0 0.005" rpy="0 0 0"/>
    <axis xyz="0 1 0" rpy="0 0 0"/>
    <parent link="cpu_holder"/>
    <child link="ckt_board"/>
  </joint>

  <link name="ic1">

    <inertial>
      <mass value="0.00001"/>
      <origin xyz="0.0 0 0" rpy="0 0 0"/>
      <inertia
        ixx="0.000001" ixy="0" ixz="0"
        iyy="0.000001" iyz="0"
        izz="0.000001"
      />
    </inertial>    

    <collision name='collision'>
      <origin xyz="0 0 0" rpy="0 0 0"/>
      <geometry>
        <mesh scale="0.7 0.7 0.7" filename="package://whereAmI/meshes/ic1.dae"/>   
      </geometry>
    </collision>
    
    <visual name="ic1_visual">
      <origin xyz="0 0 0" rpy="0 0 0"/>
      <geometry>
        <mesh scale="0.7 0.7 0.7" filename="package://whereAmI/meshes/ic1.dae"/> 
      </geometry>
    </visual>

  </link>

  <link name="ic2">

    <inertial>
      <mass value="0.00001"/>
      <origin xyz="0.0 0 0" rpy="0 0 0"/>
      <inertia
        ixx="0.000001" ixy="0" ixz="0"
        iyy="0.000001" iyz="0"
        izz="0.000001"
      />
    </inertial>    

    <collision name='collision'>
      <origin xyz="0 0 0" rpy="0 0 0"/>
      <geometry>
        <mesh scale="0.7 0.7 0.7" filename="package://whereAmI/meshes/ic2.dae"/>   
      </geometry>
    </collision>
    
    <visual name="ic2_visual">
      <origin xyz="0 0 0" rpy="0 0 0"/>
      <geometry>
        <mesh scale="0.7 0.7 0.7" filename="package://whereAmI/meshes/ic2.dae"/> 
      </geometry>
    </visual>

  </link>

  <link name="ic3">

    <inertial>
      <mass value="0.00001"/>
      <origin xyz="0.0 0 0" rpy="0 0 0"/>
      <inertia
        ixx="0.000001" ixy="0" ixz="0"
        iyy="0.000001" iyz="0"
        izz="0.000001"
      />
    </inertial>    

    <collision name='collision'>
      <origin xyz="0 0 0" rpy="0 0 0"/>
      <geometry>
        <mesh scale="0.5 0.5 0.5" filename="package://whereAmI/meshes/ic3.dae"/>   
      </geometry>
    </collision>
    
    <visual name="ic3_visual">
      <origin xyz="0 0 0" rpy="0 0 0"/>
      <geometry>
        <mesh scale="0.5 0.5 0.5" filename="package://whereAmI/meshes/ic3.dae"/> 
      </geometry>
    </visual>

  </link>

  <link name="ic4">

    <inertial>
      <mass value="0.00001"/>
      <origin xyz="0.0 0 0" rpy="0 0 0"/>
      <inertia
        ixx="0.000001" ixy="0" ixz="0"
        iyy="0.000001" iyz="0"
        izz="0.000001"
      />
    </inertial>    

    <collision name='collision'>
      <origin xyz="0 0 0" rpy="0 0 0"/>
      <geometry>
        <mesh scale="0.5 0.5 0.5" filename="package://whereAmI/meshes/ic4.dae"/>   
      </geometry>
    </collision>
    
    <visual name="ic4_visual">
      <origin xyz="0 0 0" rpy="0 0 0"/>
      <geometry>
        <mesh scale="0.5 0.5 0.5" filename="package://whereAmI/meshes/ic4.dae"/> 
      </geometry>
    </visual>

  </link>

  <link name="ic5">

    <inertial>
      <mass value="0.00001"/>
      <origin xyz="0.0 0 0" rpy="0 0 0"/>
      <inertia
        ixx="0.000001" ixy="0" ixz="0"
        iyy="0.000001" iyz="0"
        izz="0.000001"
      />
    </inertial>    

    <collision name='collision'>
      <origin xyz="0 0 0" rpy="0 0 0"/>
      <geometry>
        <mesh scale="0.7 0.7 0.7" filename="package://whereAmI/meshes/ic5.dae"/>   
      </geometry>
    </collision>
    
    <visual name="ic5_visual">
      <origin xyz="0 0 0" rpy="0 0 0"/>
      <geometry>
        <mesh scale="0.7 0.7 0.7" filename="package://whereAmI/meshes/ic5.dae"/> 
      </geometry>
    </visual>

  </link>

  <joint name="ic1_joint" type="fixed">
    <origin xyz="0 0 0.003" rpy="0 0 0"/>
    <axis xyz="0 1 0" rpy="0 0 0"/>
    <parent link="ckt_board"/>
    <child link="ic1"/>
  </joint>

  <joint name="ic2_joint" type="fixed">
    <origin xyz="0.020 0.01 0.003" rpy="0 0 0"/>
    <axis xyz="0 1 0" rpy="0 0 0"/>
    <parent link="ckt_board"/>
    <child link="ic2"/>
  </joint>

  <joint name="ic3_joint" type="fixed">
    <origin xyz="-0.020 -0.01 0.003" rpy="0 0 0"/>
    <axis xyz="0 1 0" rpy="0 0 0"/>
    <parent link="ckt_board"/>
    <child link="ic3"/>
  </joint>

  <joint name="ic4_joint" type="fixed">
    <origin xyz="-0.025 0.015 0.003" rpy="0 0 0"/>
    <axis xyz="0 1 0" rpy="0 0 0"/>
    <parent link="ckt_board"/>
    <child link="ic4"/>
  </joint>

  <joint name="ic5_joint" type="fixed">
    <origin xyz="0.010 -0.020 0.003" rpy="0 0 0"/>
    <axis xyz="0 1 0" rpy="0 0 0"/>
    <parent link="ckt_board"/>
    <child link="ic5"/>
  </joint>

  <gazebo reference="cpu_holder">
  <material>Gazebo/White</material>
  </gazebo>

  <gazebo reference="battery_holder">
  <material>Gazebo/White</material>
  </gazebo>

  <gazebo reference="battery">
  <material>Gazebo/Yellow</material>
  </gazebo>

  <gazebo reference="camera_holder">
  <material>Gazebo/Green</material>
  </gazebo>

  <gazebo reference="chassis">
  <material>Gazebo/Blue</material>
  </gazebo>

  <gazebo reference="front_right_wheel">
  <material>Gazebo/Gold</material>
  </gazebo>

  <gazebo reference="front_left_wheel">
  <material>Gazebo/Gold</material>
  </gazebo>

  <gazebo reference="rear_right_wheel">
  <material>Gazebo/Gold</material>
  </gazebo>

  <gazebo reference="rear_left_wheel">
  <material>Gazebo/Gold</material>
  </gazebo>

  <gazebo reference="camera">
  <material>Gazebo/Red</material>
  </gazebo>

  <gazebo reference="rear_right_wheel_strut">
  <material>Gazebo/LightBlueLaser</material>
  </gazebo>

  <gazebo reference="rear_left_wheel_strut">
  <material>Gazebo/LightBlueLaser</material>
  </gazebo>

  <gazebo reference="front_right_wheel_strut">
  <material>Gazebo/LightBlueLaser</material>
  </gazebo>

  <gazebo reference="front_left_wheel_strut">
  <material>Gazebo/LightBlueLaser</material>
  </gazebo>

  <gazebo reference="ckt_board">
  <material>Gazebo/Green</material>
  </gazebo>

  <gazebo reference="ic1">
  <material>Gazebo/White</material>
  </gazebo>

  <gazebo reference="ic2">
  <material>Gazebo/White</material>
  </gazebo>

  <gazebo reference="ic3">
  <material>Gazebo/White</material>
  </gazebo>

  <gazebo reference="ic4">
  <material>Gazebo/White</material>
  </gazebo>

  <gazebo reference="ic5">
  <material>Gazebo/White</material>
  </gazebo>
</robot>
